Workbook

Sheet README
A1: Tengo review: financial model
A2: Prepared 2026-10-20 for docs/review/REPORT.pdf. A model of possibilities, not a forecast of results.
A4: How it works
A5: Inputs: every number the model uses, with low, base and high values, a source URL and access date, or the label Assumption.
A6: Scenarios: Conservative uses the unfavourable end of every range, Base the central value, Ambitious the favourable end (column G gives the direction).
A7: Model: market funnel, unit economics per active user, four business models, value to a bank, impact and break-even, for all three scenarios side by side.
A8: Projection: 24 months for the recommended model (a, bank licence) in each scenario, with monthly and cumulative cash.
A9: Sensitivity: tornado tables for break-even users and for the bank value case, and a two-way table of licence fee against fixed costs.
A10: Metrics: product, forecast-quality, technical and impact metrics, with sources (test outputs and the backtest).
A12: Colour code
A13: Blue text: hard-coded inputs. Black text: formulas. Green text: links to another sheet. Yellow fill: key assumptions with no source.
A15: Important
... A18: The workbook is set to recalculate fully when opened.

Sheet Scenarios
A1: Scenario summary
A3: Output | B3: Conservative | C3: Base | D3: Ambitious
A4: Serviceable market (people) | B4: =Model!B72 | C4: =Model!C72 | D4: =Model!D72
A5: Steady-state MAU, one partner bank | B5: =Model!B76 | C5: =Model!C76 | D5: =Model!D76
A6: Variable cost per MAU per month, embedded (ZAR) | B6: =Model!B84 | C6: =Model!C84 | D6: =Model!D84
A7: Fixed cost per month (ZAR) | B7: =Model!B87 | C7: =Model!C87 | D7: =Model!D87
A8: (a) Licence: contribution per MAU per month | B8: =Model!B105 | C8: =Model!C105 | D8: =Model!D105
A9: (a) Licence: MAU to break even | B9: =Model!B112 | C9: =Model!C112 | D9: =Model!D112
A10: (b) Revenue share: contribution per MAU per month | B10: =Model!B113 | C10: =Model!C113 | D10: =Model!D113
A11: (b) Revenue share: MAU to break even | B11: =Model!B120 | C11: =Model!C120 | D11: =Model!D120
A12: (c) Consumer: contribution per MAU per month | B12: =Model!B121 | C12: =Model!C121 | D12: =Model!D121
A13: (c) Consumer: LTV to CAC | B13: =Model!B126 | C13: =Model!C126 | D13: =Model!D126
A14: (d) Sponsored: contribution per user per month | B14: =Model!B129 | C14: =Model!C129 | D14: =Model!D129
A15: Bank value per MAU per year (ZAR) | B15: =Model!B95 | C15: =Model!C95 | D15: =Model!D95
A16: Bank value per rand of licence | B16: =Model!B98 | C16: =Model!C98 | D16: =Model!D98
A17: People reached per year | B17: =Model!B138 | C17: =Model!C138 | D17: =Model!D138
A18: Days of cover gained per year | B18: =Model!B140 | C18: =Model!C140 | D18: =Model!D140
A19: Fees avoided by users per year (ZAR) | B19: =Model!B142 | C19: =Model!C142 | D19: =Model!D142
A20: First profitable month, model (a) | B20: =Projection!B14 | C20: =Projection!B30 | D20: =Projection!B46
A21: Peak funding need, model (a) (ZAR) | B21: =Projection!B15 | C21: =Projection!B31 | D21: =Projection!B47
A22: Cumulative cash at month 24, model (a) (ZAR) | B22: =Projection!B16 | C22: =Projection!B32 | D22: =Projection!B48

Sheet Inputs
A1: key | B1: description | C1: unit | D1: low | E1: base | F1: high | G1: direction | H1: source or Assumption | I1: access date | J1: notes | K1: Conservative | L1: Base | M1: Ambitious
A2: pop_total | B2: South African mid-year population 2026 | C2: people | D2: 63100945 | E2: 63522380 | F2: 63522380 | G2: + | H2: https://www.statssa.gov.za/publications/P0302/P03022026.pdf (Table 1) | I2: 2026-10-20 | J2: Low is the 2025 estimate from https://www.statssa.gov.za/?p=18613 | K2: =IF($G2="+",MIN(D2,F2),MAX(D2,F2)) | L2: =E2 | M2: =IF($G2="+",MAX(D2,F2),MIN(D2,F2))
A3: pop_15plus | B3: Population aged 15 and over, 2026 | C3: people | D3: 46700000 | E3: 47276319 | F3: 47276319 | G3: + | H3: Derived from https://www.statssa.gov.za/publications/P0302/P03022026.pdf (Table 5) | I3: 2026-10-20 | J3: 63 522 380 minus ages 0 to 14 (5 325 401 + 5 448 245 + 5 472 415). Low is Findex population 15+ (46.7m) | K3: =IF($G3="+",MIN(D3,F3),MAX(D3,F3)) | L3: =E3 | M3: =IF($G3="+",MAX(D3,F3),MIN(D3,F3))
A4: pop_18plus | B4: Adults aged 18 and over, 2026 (estimate) | C4: people | D4: 43300000 | E4: 43905000 | F4: 44500000 | G4: + | H4: Derived from Stats SA Table 5 plus Assumption | I4: 2026-10-20 | J4: 15+ minus 3/5 of the 15 to 19 cohort (5 618 124). Assumes even spread by single year of age | K4: =IF($G4="+",MIN(D4,F4),MAX(D4,F4)) | L4: =E4 | M4: =IF($G4="+",MAX(D4,F4),MIN(D4,F4))
A5: acct_ownership | B5: Adults 15+ with any account (bank, FI or mobile money), 2024 | C5: fraction | D5: 0.784 | E5: 0.811 | F5: 0.854 | G5: + | H5: https://thedocs.worldbank.org/en/doc/be6615202d1f08a25855c8ac2d615122-0050012025/related/Little-Data-Book-2025-Web.pdf (South Africa page) | I5: 2026-10-20 | J5: Global Findex 2025. Low is bank or FI account only (78.4). High is the 2021 value (85.4). Ownership fell from 2021 to 2024 | K5: =IF($G5="+",MIN(D5,F5),MAX(D5,F5)) | L5: =E5 | M5: =IF($G5="+",MAX(D5,F5),MIN(D5,F5))
A6: acct_digital_enabled | B6: Adults 15+ with an account used with a card or phone | C6: fraction | D6: 0.6 | E6: 0.678 | F6: 0.72 | G6: + | H6: Same Little Data Book, South Africa page | I6: 2026-10-20 | J6: Range is Assumption around the point value | K6: =IF($G6="+",MIN(D6,F6),MAX(D6,F6)) | L6: =E6 | M6: =IF($G6="+",MAX(D6,F6),MIN(D6,F6))
A7: acct_poorest40 | B7: Account ownership, poorest 40 percent of households | C7: fraction | D7: 0.7 | E7: 0.742 | F7: 0.78 | G7: + | H7: Same Little Data Book, South Africa page | I7: 2026-10-20 | J7: Range Assumption | K7: =IF($G7="+",MIN(D7,F7),MAX(D7,F7)) | L7: =E7 | M7: =IF($G7="+",MAX(D7,F7),MIN(D7,F7))
A8: smartphone_own | B8: Adults 15+ with a personal smartphone | C8: fraction | D8: 0.526 | E8: 0.675 | F8: 0.75 | G8: + | H8: Same Little Data Book, South Africa page | I8: 2026-10-20 | J8: Low is the poorest 40 percent (52.6). High is Assumption for 2026 growth | K8: =IF($G8="+",MIN(D8,F8),MAX(D8,F8)) | L8: =E8 | M8: =IF($G8="+",MAX(D8,F8),MIN(D8,F8))
A9: mobile_phone_own | B9: Adults 15+ with any personal mobile phone | C9: fraction | D9: 0.825 | E9: 0.87 | F9: 0.9 | G9: + | H9: Same Little Data Book, South Africa page | I9: 2026-10-20 | J9: Relevant to SMS reach. Low is poorest 40 percent | K9: =IF($G9="+",MIN(D9,F9),MAX(D9,F9)) | L9: =E9 | M9: =IF($G9="+",MAX(D9,F9),MIN(D9,F9))
A10: internet_users | B10: Internet users, October 2025 | C10: people | D10: 50000000 | E10: 51700000 | F10: 52500000 | G10: + | H10: https://datareportal.com/reports/digital-2026-south-africa | I10: 2026-10-20 | J10: 79.6 percent penetration. Range Assumption | K10: =IF($G10="+",MIN(D10,F10),MAX(D10,F10)) | L10: =E10 | M10: =IF($G10="+",MAX(D10,F10),MIN(D10,F10))
A11: internet_pen | B11: Internet penetration of total population | C11: fraction | D11: 0.75 | E11: 0.796 | F11: 0.82 | G11: + | H11: https://datareportal.com/reports/digital-2026-south-africa | I11: 2026-10-20 | J11: Range Assumption | K11: =IF($G11="+",MIN(D11,F11),MAX(D11,F11)) | L11: =E11 | M11: =IF($G11="+",MAX(D11,F11),MIN(D11,F11))
A12: employed | B12: Employed persons, QLFS Q2 2026 | C12: people | D12: 16700000 | E12: 16700000 | F12: 16700000 | G12: + | H12: https://www.sanews.gov.za/south-africa/sa-official-unemployment-rate-rises-336 and https://www.statssa.gov.za/publications/P0211/Media%20Release%20QLFS%20Q2%202026.pdf | I12: 2026-10-20 | J12: Released 11 August 2026 | K12: =IF($G12="+",MIN(D12,F12),MAX(D12,F12)) | L12: =E12 | M12: =IF($G12="+",MAX(D12,F12),MIN(D12,F12))
A13: unemployed | B13: Unemployed persons, QLFS Q2 2026 | C13: people | D13: 8500000 | E13: 8500000 | F13: 8500000 | G13: + | H13: Same as above | I13: 2026-10-20 | J13: Official rate 33.6 percent | K13: =IF($G13="+",MIN(D13,F13),MAX(D13,F13)) | L13: =E13 | M13: =IF($G13="+",MAX(D13,F13),MIN(D13,F13))
... A46: db_compute | B46: Supabase compute add-on (Large) | C46: USD per month | D46: 15 | E46: 110 | F46: 410 | G46: - | H46: https://supabase.com/pricing | I46: 2026-10-20 | J46: Low is Small, high is 2XL. A bank will likely require hosting in its own cloud tenancy, which changes this line entirely | K46: =IF($G46="+",MIN(D46,F46),MAX(D46,F46)) | L46: =E46 | M46: =IF($G46="+",MAX(D46,F46),MIN(D46,F46))
A47: db_egress_overage | B47: Egress above included 250 GB | C47: USD per GB | D47: 0.09 | E47: 0.09 | F47: 0.09 | G47: - | H47: https://supabase.com/pricing | I47: 2026-10-20 | K47: =IF($G47="+",MIN(D47,F47),MAX(D47,F47)) | L47: =E47 | M47: =IF($G47="+",MAX(D47,F47),MIN(D47,F47))
A48: hosting_per_mau | B48: All-in cloud, database and hosting cost per MAU | C48: ZAR per MAU per month | D48: 0.05 | E48: 0.15 | F48: 0.6 | G48: - | H48: Assumption | I48: 2026-10-20 | J48: Fixed base above spread over 20k to 200k MAU, plus storage of about 2 000 transactions per user. Bank tenancy or on-premises could be higher | K48: =IF($G48="+",MIN(D48,F48),MAX(D48,F48)) | L48: =E48 | M48: =IF($G48="+",MAX(D48,F48),MIN(D48,F48))
A49: forecast_compute | B49: Forecast engine compute per MAU | C49: ZAR per MAU per month | D49: 0.005 | E49: 0.02 | F49: 0.1 | G49: - | H49: Assumption | I49: 2026-10-20 | J49: Engine is pure TypeScript percentile maths (`src/engine/forecast.ts`); one run per user per day is negligible | K49: =IF($G49="+",MIN(D49,F49),MAX(D49,F49)) | L49: =E49 | M49: =IF($G49="+",MAX(D49,F49),MIN(D49,F49))
A50: llm_in_price | B50: Claude Haiku 5.5 input price (prompts up to 100K tokens) | C50: USD per million tokens | D50: 0.1 | E50: 0.1 | F50: 2 | G50: - | H50: https://claude.com/pricing | I50: 2026-10-20 | J50: High is Sonnet 5.5 input | K50: =IF($G50="+",MIN(D50,F50),MAX(D50,F50)) | L50: =E50 | M50: =IF($G50="+",MAX(D50,F50),MIN(D50,F50))
A51: llm_out_price | B51: Claude Haiku 5.5 output price | C51: USD per million tokens | D51: 0.5 | E51: 0.5 | F51: 10 | G51: - | H51: https://claude.com/pricing | I51: 2026-10-20 | J51: High is Sonnet 5.5 output. Batch processing is 50 percent off (same page) | K51: =IF($G51="+",MIN(D51,F51),MAX(D51,F51)) | L51: =E51 | M51: =IF($G51="+",MAX(D51,F51),MIN(D51,F51))
A52: tokens_in_msg | B52: Input tokens per generated message | C52: tokens | D52: 300 | E52: 600 | F52: 1500 | G52: - | H52: Assumption | I52: 2026-10-20 | J52: System prompt, forecast summary and language instruction | K52: =IF($G52="+",MIN(D52,F52),MAX(D52,F52)) | L52: =E52 | M52: =IF($G52="+",MAX(D52,F52),MIN(D52,F52))
A53: tokens_out_msg | B53: Output tokens per generated message | C53: tokens | D53: 60 | E53: 120 | F53: 250 | G53: - | H53: Assumption | I53: 2026-10-20 | J53: WhatsApp template in `src/messages/templates.ts` is five short lines | K53: =IF($G53="+",MIN(D53,F53),MAX(D53,F53)) | L53: =E53 | M53: =IF($G53="+",MAX(D53,F53),MIN(D53,F53))
A54: msgs_per_month | B54: Proactive messages per MAU per month | C54: messages | D54: 4 | E54: 8 | F54: 30 | G54: - | H54: Assumption | I54: 2026-10-20 | J54: Brief describes a daily message (30). Base is twice weekly plus state changes, because daily paid messaging breaks the unit economics (see commercial.md COMM-03) | K54: =IF($G54="+",MIN(D54,F54),MAX(D54,F54)) | L54: =E54 | M54: =IF($G54="+",MAX(D54,F54),MIN(D54,F54))
A55: wa_utility | B55: WhatsApp utility template message, South Africa, from 1 Oct 2026 | C55: USD per delivered message | D55: 0.0071 | E55: 0.0095 | F55: 0.0379 | G55: - | H55: https://chatmaxima.com/whatsapp-api-pricing/south-africa/ | I55: 2026-10-20 | J55: Meta's own page https://developers.facebook.com/docs/whatsapp/pricing confirms a utility increase for South Africa on 1 Oct 2026 but the amount was in a linked CSV not read. Low applies the maximum 25 percent volume tier. High is the marketing rate, if Meta classes daily nudges as marketing. Excludes VAT and BSP fees | K55: =IF($G55="+",MIN(D55,F55),MAX(D55,F55)) | L55: =E55 | M55: =IF($G55="+",MAX(D55,F55),MIN(D55,F55))
A56: wa_marketing | B56: WhatsApp marketing template message, South Africa | C56: USD per delivered message | D56: 0.0379 | E56: 0.0379 | F56: 0.0379 | G56: - | H56: https://chatmaxima.com/whatsapp-api-pricing/south-africa/ | I56: 2026-10-20 | J56: Reseller page quoting Meta list rate. Not tiered | K56: =IF($G56="+",MIN(D56,F56),MAX(D56,F56)) | L56: =E56 | M56: =IF($G56="+",MAX(D56,F56),MIN(D56,F56))
A57: wa_service_free | B57: Free service messages per phone number per month | C57: messages | D57: 1000 | E57: 1000 | F57: 1000 | G57: + | H57: https://chatmaxima.com/whatsapp-api-pricing/south-africa/ | I57: 2026-10-20 | J57: Only user-initiated conversations. Utility inside an open 24 hour window is free | K57: =IF($G57="+",MIN(D57,F57),MAX(D57,F57)) | L57: =E57 | M57: =IF($G57="+",MAX(D57,F57),MIN(D57,F57))
A58: wa_bsp_fee | B58: Business solution provider fee per message | C58: ZAR per message | D58: 0 | E58: 0.05 | F58: 0.15 | G58: - | H58: Assumption | I58: 2026-10-20 | J58: BSPs add platform fees (noted on the ChatMaxima page) but no SA rate card was found | K58: =IF($G58="+",MIN(D58,F58),MAX(D58,F58)) | L58: =E58 | M58: =IF($G58="+",MAX(D58,F58),MIN(D58,F58))
A59: sms_price | B59: Bulk SMS to South Africa, 0 to 10 000 per month | C59: ZAR per SMS excl. VAT | D59: 0.14 | E59: 0.24 | F59: 0.24 | G59: - | H59: https://www.panaceamobile.com/gateways/bulk-sms-gateway/ | I59: 2026-10-20 | J59: Panacea tiers fall to R0.17 at 250k+. Low is SMSFlow 14c reported at https://www.itweb.co.za/office/datanamix/content/xA9POvNE6a9qo4J8 (sponsored article) | K59: =IF($G59="+",MIN(D59,F59),MAX(D59,F59)) | L59: =E59 | M59: =IF($G59="+",MAX(D59,F59),MIN(D59,F59))
... A81: capitec_returned_do | B81: Capitec returned debit order fee (insufficient funds), personal | C81: ZAR per item | D81: 6 | E81: 6 | F81: 6 | G81: + | H81: https://www.capitecbank.co.za/globalassets/pages/documents-library/transact/personal-banking-fees-2026.pdf | I81: 2026-10-20 | J81: Valid from 1 March 2026 | K81: =IF($G81="+",MIN(D81,F81),MAX(D81,F81)) | L81: =E81 | M81: =IF($G81="+",MAX(D81,F81),MIN(D81,F81))
A82: capitec_do_fee | B82: Capitec debit order fee | C82: ZAR per item | D82: 3 | E82: 3 | F82: 3 | G82: + | H82: Same Capitec PDF | I82: 2026-10-20 | K82: =IF($G82="+",MIN(D82,F82),MAX(D82,F82)) | L82: =E82 | M82: =IF($G82="+",MAX(D82,F82),MIN(D82,F82))
A83: capitec_monthly_fee | B83: Capitec main account monthly fee | C83: ZAR per month | D83: 7.5 | E83: 7.5 | F83: 7.5 | G83: + | H83: Same Capitec PDF | I83: 2026-10-20 | J83: Price anchor for the segment | K83: =IF($G83="+",MIN(D83,F83),MAX(D83,F83)) | L83: =E83 | M83: =IF($G83="+",MAX(D83,F83),MIN(D83,F83))
A84: sb_unpaid_payt | B84: Standard Bank Access Account unpaid debit order, pay as you transact | C84: ZAR per item | D84: 25 | E84: 25 | F84: 25 | G84: + | H84: https://www.standardbank.co.za/static_file/South%20Africa/PDF/Personal%20Pricing/2026/Access_Account_Pricing_Guide_2026.pdf | I84: 2026-10-20 | J84: 2026 guide | K84: =IF($G84="+",MIN(D84,F84),MAX(D84,F84)) | L84: =E84 | M84: =IF($G84="+",MAX(D84,F84),MIN(D84,F84))
A85: sb_unpaid_bundle | B85: Standard Bank Access Account bundle: unpaid debit orders after 3 free per 12 months | C85: ZAR per item | D85: 130 | E85: 130 | F85: 130 | G85: + | H85: Same Standard Bank PDF | I85: 2026-10-20 | J85: First 3 in a rolling 12 months are free | K85: =IF($G85="+",MIN(D85,F85),MAX(D85,F85)) | L85: =E85 | M85: =IF($G85="+",MAX(D85,F85),MIN(D85,F85))
A86: sb_business_unpaid | B86: Standard Bank business current account unpaid debit order | C86: ZAR per item | D86: 155 | E86: 155 | F86: 155 | G86: + | H86: https://www.standardbank.co.za/static_file/South%20Africa/PDF/Business%20Pricing/2026/Business%20Current%20Account%20Pricing%20Guide%202026.pdf | I86: 2026-10-20 | J86: From search snippet, not opened. Relevant for spaza owners on business accounts | K86: =IF($G86="+",MIN(D86,F86),MAX(D86,F86)) | L86: =E86 | M86: =IF($G86="+",MAX(D86,F86),MIN(D86,F86))
A87: fnb_unpaid_fee | B87: FNB personal unpaid debit order fee | C87: ZAR per item | D87: 0 | E87: 0 | F87: 0 | G87: + | H87: Not sourced | I87: 2026-10-20 | J87: fnb.co.za pricing pages returned a bot check and the 2025/26 SA guide was not retrievable. Use Capitec and Standard Bank as the range until the FNB guide is checked by hand | K87: =IF($G87="+",MIN(D87,F87),MAX(D87,F87)) | L87: =E87 | M87: =IF($G87="+",MAX(D87,F87),MIN(D87,F87))
A88: repo_rate | B88: SARB repo rate | C88: fraction | D88: 0.07 | E88: 0.07 | F88: 0.0725 | G88: + | H88: https://www.ewn.co.za/2026/07/23/sarb-keeps-interest-rates-unchanged-surprising-markets-and-analysts | I88: 2026-10-20 | J88: July 2026 hold at 7 percent. High is a single-source report of a September hike to 7.25 at https://briefly.co.za/business-economy/money/254111-sarb-raises-repo-rate-725-what-means-bills-sa/ | K88: =IF($G88="+",MIN(D88,F88),MAX(D88,F88)) | L88: =E88 | M88: =IF($G88="+",MAX(D88,F88),MIN(D88,F88))
A89: nca_cap_unsecured | B89: NCA maximum rate, unsecured credit | C89: fraction | D89: 0.21 | E89: 0.21 | F89: 0.21 | G89: + | H89: https://mjkinc.co.za/finance-credit-law/interest-cap-and-in-duplum-calculator | I89: 2026-10-20 | J89: Regulation 42 Table A per a law firm summary. 28 percent at 7 percent repo | K89: =IF($G89="+",MIN(D89,F89),MAX(D89,F89)) | L89: =E89 | M89: =IF($G89="+",MAX(D89,F89),MIN(D89,F89))
A90: nca_cap_facility | B90: NCA maximum rate, credit facilities (cards, overdrafts likely) | C90: fraction | D90: 0.14 | E90: 0.14 | F90: 0.14 | G90: + | H90: Same page | I90: 2026-10-20 | J90: Whether overdrafts fall here is not confirmed by the source | K90: =IF($G90="+",MIN(D90,F90),MAX(D90,F90)) | L90: =E90 | M90: =IF($G90="+",MAX(D90,F90),MIN(D90,F90))
A91: pasa_unpaid_benchmark | B91: Acceptable unpaid debit order ratio for collectors | C91: fraction | D91: 0.04 | E91: 0.1 | F91: 0.1 | G91: + | H91: https://help.netcash.co.za/?p=9799 | I91: 2026-10-20 | J91: Undated. Low is 2016 PASA data (1.2m unpaid of 31m a month, 3.9 percent) at https://businesstech.co.za/news/?p=136339 | K91: =IF($G91="+",MIN(D91,F91),MAX(D91,F91)) | L91: =E91 | M91: =IF($G91="+",MAX(D91,F91),MIN(D91,F91))
A92: share_users_unpaid | B92: Share of target users with at least one unpaid debit order a year | C92: fraction | D92: 0.1 | E92: 0.25 | F92: 0.4 | G92: + | H92: Assumption | I92: 2026-10-20 | J92: Informed by 41 percent of credit-active consumers in default (credit_default_share) | K92: =IF($G92="+",MIN(D92,F92),MAX(D92,F92)) | L92: =E92 | M92: =IF($G92="+",MAX(D92,F92),MIN(D92,F92))
A93: unpaid_events_per_user | B93: Unpaid events a year among affected users | C93: events per year | D93: 1 | E93: 2 | F93: 4 | G93: + | H93: Assumption | I93: 2026-10-20 | K93: =IF($G93="+",MIN(D93,F93),MAX(D93,F93)) | L93: =E93 | M93: =IF($G93="+",MAX(D93,F93),MIN(D93,F93))
...

Sheet Model
A1: Model: three scenarios side by side
A3: Line | B3: Conservative | C3: Base | D3: Ambitious | E3: Formula or note
A4: Inputs used (linked from the Inputs sheet)
A5: Input: pop_15plus | B5: =INDEX(Inputs!$K$2:$K$121,MATCH("pop_15plus",Inputs!$A$2:$A$121,0)) | C5: =INDEX(Inputs!$L$2:$L$121,MATCH("pop_15plus",Inputs!$A$2:$A$121,0)) | D5: =INDEX(Inputs!$M$2:$M$121,MATCH("pop_15plus",Inputs!$A$2:$A$121,0)) | E5: From Inputs, key pop_15plus
A6: Input: acct_ownership | B6: =INDEX(Inputs!$K$2:$K$121,MATCH("acct_ownership",Inputs!$A$2:$A$121,0)) | C6: =INDEX(Inputs!$L$2:$L$121,MATCH("acct_ownership",Inputs!$A$2:$A$121,0)) | D6: =INDEX(Inputs!$M$2:$M$121,MATCH("acct_ownership",Inputs!$A$2:$A$121,0)) | E6: From Inputs, key acct_ownership
A7: Input: smartphone_own | B7: =INDEX(Inputs!$K$2:$K$121,MATCH("smartphone_own",Inputs!$A$2:$A$121,0)) | C7: =INDEX(Inputs!$L$2:$L$121,MATCH("smartphone_own",Inputs!$A$2:$A$121,0)) | D7: =INDEX(Inputs!$M$2:$M$121,MATCH("smartphone_own",Inputs!$A$2:$A$121,0)) | E7: From Inputs, key smartphone_own
A8: Input: informal_sector_emp | B8: =INDEX(Inputs!$K$2:$K$121,MATCH("informal_sector_emp",Inputs!$A$2:$A$121,0)) | C8: =INDEX(Inputs!$L$2:$L$121,MATCH("informal_sector_emp",Inputs!$A$2:$A$121,0)) | D8: =INDEX(Inputs!$M$2:$M$121,MATCH("informal_sector_emp",Inputs!$A$2:$A$121,0)) | E8: From Inputs, key informal_sector_emp
A9: Input: household_sector_emp | B9: =INDEX(Inputs!$K$2:$K$121,MATCH("household_sector_emp",Inputs!$A$2:$A$121,0)) | C9: =INDEX(Inputs!$L$2:$L$121,MATCH("household_sector_emp",Inputs!$A$2:$A$121,0)) | D9: =INDEX(Inputs!$M$2:$M$121,MATCH("household_sector_emp",Inputs!$A$2:$A$121,0)) | E9: From Inputs, key household_sector_emp
A10: Input: tam_irregular_adults | B10: =INDEX(Inputs!$K$2:$K$121,MATCH("tam_irregular_adults",Inputs!$A$2:$A$121,0)) | C10: =INDEX(Inputs!$L$2:$L$121,MATCH("tam_irregular_adults",Inputs!$A$2:$A$121,0)) | D10: =INDEX(Inputs!$M$2:$M$121,MATCH("tam_irregular_adults",Inputs!$A$2:$A$121,0)) | E10: From Inputs, key tam_irregular_adults
A11: Input: sam_share_banked_smartphone | B11: =INDEX(Inputs!$K$2:$K$121,MATCH("sam_share_banked_smartphone",Inputs!$A$2:$A$121,0)) | C11: =INDEX(Inputs!$L$2:$L$121,MATCH("sam_share_banked_smartphone",Inputs!$A$2:$A$121,0)) | D11: =INDEX(Inputs!$M$2:$M$121,MATCH("sam_share_banked_smartphone",Inputs!$A$2:$A$121,0)) | E11: From Inputs, key sam_share_banked_smartphone
A12: Input: partner_base | B12: =INDEX(Inputs!$K$2:$K$121,MATCH("partner_base",Inputs!$A$2:$A$121,0)) | C12: =INDEX(Inputs!$L$2:$L$121,MATCH("partner_base",Inputs!$A$2:$A$121,0)) | D12: =INDEX(Inputs!$M$2:$M$121,MATCH("partner_base",Inputs!$A$2:$A$121,0)) | E12: From Inputs, key partner_base
A13: Input: share_partner_irregular | B13: =INDEX(Inputs!$K$2:$K$121,MATCH("share_partner_irregular",Inputs!$A$2:$A$121,0)) | C13: =INDEX(Inputs!$L$2:$L$121,MATCH("share_partner_irregular",Inputs!$A$2:$A$121,0)) | D13: =INDEX(Inputs!$M$2:$M$121,MATCH("share_partner_irregular",Inputs!$A$2:$A$121,0)) | E13: From Inputs, key share_partner_irregular
A14: Input: share_eligible_offered | B14: =INDEX(Inputs!$K$2:$K$121,MATCH("share_eligible_offered",Inputs!$A$2:$A$121,0)) | C14: =INDEX(Inputs!$L$2:$L$121,MATCH("share_eligible_offered",Inputs!$A$2:$A$121,0)) | D14: =INDEX(Inputs!$M$2:$M$121,MATCH("share_eligible_offered",Inputs!$A$2:$A$121,0)) | E14: From Inputs, key share_eligible_offered
A15: Input: offered_to_activated | B15: =INDEX(Inputs!$K$2:$K$121,MATCH("offered_to_activated",Inputs!$A$2:$A$121,0)) | C15: =INDEX(Inputs!$L$2:$L$121,MATCH("offered_to_activated",Inputs!$A$2:$A$121,0)) | D15: =INDEX(Inputs!$M$2:$M$121,MATCH("offered_to_activated",Inputs!$A$2:$A$121,0)) | E15: From Inputs, key offered_to_activated
A16: Input: activated_to_mau | B16: =INDEX(Inputs!$K$2:$K$121,MATCH("activated_to_mau",Inputs!$A$2:$A$121,0)) | C16: =INDEX(Inputs!$L$2:$L$121,MATCH("activated_to_mau",Inputs!$A$2:$A$121,0)) | D16: =INDEX(Inputs!$M$2:$M$121,MATCH("activated_to_mau",Inputs!$A$2:$A$121,0)) | E16: From Inputs, key activated_to_mau
A17: Input: sponsor_reach | B17: =INDEX(Inputs!$K$2:$K$121,MATCH("sponsor_reach",Inputs!$A$2:$A$121,0)) | C17: =INDEX(Inputs!$L$2:$L$121,MATCH("sponsor_reach",Inputs!$A$2:$A$121,0)) | D17: =INDEX(Inputs!$M$2:$M$121,MATCH("sponsor_reach",Inputs!$A$2:$A$121,0)) | E17: From Inputs, key sponsor_reach
A18: Input: usd_zar | B18: =INDEX(Inputs!$K$2:$K$121,MATCH("usd_zar",Inputs!$A$2:$A$121,0)) | C18: =INDEX(Inputs!$L$2:$L$121,MATCH("usd_zar",Inputs!$A$2:$A$121,0)) | D18: =INDEX(Inputs!$M$2:$M$121,MATCH("usd_zar",Inputs!$A$2:$A$121,0)) | E18: From Inputs, key usd_zar
A19: Input: vat | B19: =INDEX(Inputs!$K$2:$K$121,MATCH("vat",Inputs!$A$2:$A$121,0)) | C19: =INDEX(Inputs!$L$2:$L$121,MATCH("vat",Inputs!$A$2:$A$121,0)) | D19: =INDEX(Inputs!$M$2:$M$121,MATCH("vat",Inputs!$A$2:$A$121,0)) | E19: From Inputs, key vat
A20: Input: hosting_per_mau | B20: =INDEX(Inputs!$K$2:$K$121,MATCH("hosting_per_mau",Inputs!$A$2:$A$121,0)) | C20: =INDEX(Inputs!$L$2:$L$121,MATCH("hosting_per_mau",Inputs!$A$2:$A$121,0)) | D20: =INDEX(Inputs!$M$2:$M$121,MATCH("hosting_per_mau",Inputs!$A$2:$A$121,0)) | E20: From Inputs, key hosting_per_mau
A21: Input: forecast_compute | B21: =INDEX(Inputs!$K$2:$K$121,MATCH("forecast_compute",Inputs!$A$2:$A$121,0)) | C21: =INDEX(Inputs!$L$2:$L$121,MATCH("forecast_compute",Inputs!$A$2:$A$121,0)) | D21: =INDEX(Inputs!$M$2:$M$121,MATCH("forecast_compute",Inputs!$A$2:$A$121,0)) | E21: From Inputs, key forecast_compute
A22: Input: llm_in_price | B22: =INDEX(Inputs!$K$2:$K$121,MATCH("llm_in_price",Inputs!$A$2:$A$121,0)) | C22: =INDEX(Inputs!$L$2:$L$121,MATCH("llm_in_price",Inputs!$A$2:$A$121,0)) | D22: =INDEX(Inputs!$M$2:$M$121,MATCH("llm_in_price",Inputs!$A$2:$A$121,0)) | E22: From Inputs, key llm_in_price
A23: Input: llm_out_price | B23: =INDEX(Inputs!$K$2:$K$121,MATCH("llm_out_price",Inputs!$A$2:$A$121,0)) | C23: =INDEX(Inputs!$L$2:$L$121,MATCH("llm_out_price",Inputs!$A$2:$A$121,0)) | D23: =INDEX(Inputs!$M$2:$M$121,MATCH("llm_out_price",Inputs!$A$2:$A$121,0)) | E23: From Inputs, key llm_out_price
A24: Input: tokens_in_msg | B24: =INDEX(Inputs!$K$2:$K$121,MATCH("tokens_in_msg",Inputs!$A$2:$A$121,0)) | C24: =INDEX(Inputs!$L$2:$L$121,MATCH("tokens_in_msg",Inputs!$A$2:$A$121,0)) | D24: =INDEX(Inputs!$M$2:$M$121,MATCH("tokens_in_msg",Inputs!$A$2:$A$121,0)) | E24: From Inputs, key tokens_in_msg
A25: Input: tokens_out_msg | B25: =INDEX(Inputs!$K$2:$K$121,MATCH("tokens_out_msg",Inputs!$A$2:$A$121,0)) | C25: =INDEX(Inputs!$L$2:$L$121,MATCH("tokens_out_msg",Inputs!$A$2:$A$121,0)) | D25: =INDEX(Inputs!$M$2:$M$121,MATCH("tokens_out_msg",Inputs!$A$2:$A$121,0)) | E25: From Inputs, key tokens_out_msg
A26: Input: msgs_per_month | B26: =INDEX(Inputs!$K$2:$K$121,MATCH("msgs_per_month",Inputs!$A$2:$A$121,0)) | C26: =INDEX(Inputs!$L$2:$L$121,MATCH("msgs_per_month",Inputs!$A$2:$A$121,0)) | D26: =INDEX(Inputs!$M$2:$M$121,MATCH("msgs_per_month",Inputs!$A$2:$A$121,0)) | E26: From Inputs, key msgs_per_month
A27: Input: wa_utility | B27: =INDEX(Inputs!$K$2:$K$121,MATCH("wa_utility",Inputs!$A$2:$A$121,0)) | C27: =INDEX(Inputs!$L$2:$L$121,MATCH("wa_utility",Inputs!$A$2:$A$121,0)) | D27: =INDEX(Inputs!$M$2:$M$121,MATCH("wa_utility",Inputs!$A$2:$A$121,0)) | E27: From Inputs, key wa_utility
A28: Input: wa_bsp_fee | B28: =INDEX(Inputs!$K$2:$K$121,MATCH("wa_bsp_fee",Inputs!$A$2:$A$121,0)) | C28: =INDEX(Inputs!$L$2:$L$121,MATCH("wa_bsp_fee",Inputs!$A$2:$A$121,0)) | D28: =INDEX(Inputs!$M$2:$M$121,MATCH("wa_bsp_fee",Inputs!$A$2:$A$121,0)) | E28: From Inputs, key wa_bsp_fee
A29: Input: sms_price | B29: =INDEX(Inputs!$K$2:$K$121,MATCH("sms_price",Inputs!$A$2:$A$121,0)) | C29: =INDEX(Inputs!$L$2:$L$121,MATCH("sms_price",Inputs!$A$2:$A$121,0)) | D29: =INDEX(Inputs!$M$2:$M$121,MATCH("sms_price",Inputs!$A$2:$A$121,0)) | E29: From Inputs, key sms_price
A30: Input: push_cost | B30: =INDEX(Inputs!$K$2:$K$121,MATCH("push_cost",Inputs!$A$2:$A$121,0)) | C30: =INDEX(Inputs!$L$2:$L$121,MATCH("push_cost",Inputs!$A$2:$A$121,0)) | D30: =INDEX(Inputs!$M$2:$M$121,MATCH("push_cost",Inputs!$A$2:$A$121,0)) | E30: From Inputs, key push_cost
A31: Input: support_per_mau | B31: =INDEX(Inputs!$K$2:$K$121,MATCH("support_per_mau",Inputs!$A$2:$A$121,0)) | C31: =INDEX(Inputs!$L$2:$L$121,MATCH("support_per_mau",Inputs!$A$2:$A$121,0)) | D31: =INDEX(Inputs!$M$2:$M$121,MATCH("support_per_mau",Inputs!$A$2:$A$121,0)) | E31: From Inputs, key support_per_mau
A32: Input: compliance_fixed | B32: =INDEX(Inputs!$K$2:$K$121,MATCH("compliance_fixed",Inputs!$A$2:$A$121,0)) | C32: =INDEX(Inputs!$L$2:$L$121,MATCH("compliance_fixed",Inputs!$A$2:$A$121,0)) | D32: =INDEX(Inputs!$M$2:$M$121,MATCH("compliance_fixed",Inputs!$A$2:$A$121,0)) | E32: From Inputs, key compliance_fixed
A33: Input: team_fixed | B33: =INDEX(Inputs!$K$2:$K$121,MATCH("team_fixed",Inputs!$A$2:$A$121,0)) | C33: =INDEX(Inputs!$L$2:$L$121,MATCH("team_fixed",Inputs!$A$2:$A$121,0)) | D33: =INDEX(Inputs!$M$2:$M$121,MATCH("team_fixed",Inputs!$A$2:$A$121,0)) | E33: From Inputs, key team_fixed
A34: Input: db_base | B34: =INDEX(Inputs!$K$2:$K$121,MATCH("db_base",Inputs!$A$2:$A$121,0)) | C34: =INDEX(Inputs!$L$2:$L$121,MATCH("db_base",Inputs!$A$2:$A$121,0)) | D34: =INDEX(Inputs!$M$2:$M$121,MATCH("db_base",Inputs!$A$2:$A$121,0)) | E34: From Inputs, key db_base
A35: Input: payfast_card_pct | B35: =INDEX(Inputs!$K$2:$K$121,MATCH("payfast_card_pct",Inputs!$A$2:$A$121,0)) | C35: =INDEX(Inputs!$L$2:$L$121,MATCH("payfast_card_pct",Inputs!$A$2:$A$121,0)) | D35: =INDEX(Inputs!$M$2:$M$121,MATCH("payfast_card_pct",Inputs!$A$2:$A$121,0)) | E35: From Inputs, key payfast_card_pct
A36: Input: payfast_card_fixed | B36: =INDEX(Inputs!$K$2:$K$121,MATCH("payfast_card_fixed",Inputs!$A$2:$A$121,0)) | C36: =INDEX(Inputs!$L$2:$L$121,MATCH("payfast_card_fixed",Inputs!$A$2:$A$121,0)) | D36: =INDEX(Inputs!$M$2:$M$121,MATCH("payfast_card_fixed",Inputs!$A$2:$A$121,0)) | E36: From Inputs, key payfast_card_fixed
A37: Input: lic_fee_per_mau | B37: =INDEX(Inputs!$K$2:$K$121,MATCH("lic_fee_per_mau",Inputs!$A$2:$A$121,0)) | C37: =INDEX(Inputs!$L$2:$L$121,MATCH("lic_fee_per_mau",Inputs!$A$2:$A$121,0)) | D37: =INDEX(Inputs!$M$2:$M$121,MATCH("lic_fee_per_mau",Inputs!$A$2:$A$121,0)) | E37: From Inputs, key lic_fee_per_mau
A38: Input: lic_pilot_fee | B38: =INDEX(Inputs!$K$2:$K$121,MATCH("lic_pilot_fee",Inputs!$A$2:$A$121,0)) | C38: =INDEX(Inputs!$L$2:$L$121,MATCH("lic_pilot_fee",Inputs!$A$2:$A$121,0)) | D38: =INDEX(Inputs!$M$2:$M$121,MATCH("lic_pilot_fee",Inputs!$A$2:$A$121,0)) | E38: From Inputs, key lic_pilot_fee
A39: Input: lic_platform_floor | B39: =INDEX(Inputs!$K$2:$K$121,MATCH("lic_platform_floor",Inputs!$A$2:$A$121,0)) | C39: =INDEX(Inputs!$L$2:$L$121,MATCH("lic_platform_floor",Inputs!$A$2:$A$121,0)) | D39: =INDEX(Inputs!$M$2:$M$121,MATCH("lic_platform_floor",Inputs!$A$2:$A$121,0)) | E39: From Inputs, key lic_platform_floor
A40: Input: outcome_share | B40: =INDEX(Inputs!$K$2:$K$121,MATCH("outcome_share",Inputs!$A$2:$A$121,0)) | C40: =INDEX(Inputs!$L$2:$L$121,MATCH("outcome_share",Inputs!$A$2:$A$121,0)) | D40: =INDEX(Inputs!$M$2:$M$121,MATCH("outcome_share",Inputs!$A$2:$A$121,0)) | E40: From Inputs, key outcome_share
A41: Input: sub_price | B41: =INDEX(Inputs!$K$2:$K$121,MATCH("sub_price",Inputs!$A$2:$A$121,0)) | C41: =INDEX(Inputs!$L$2:$L$121,MATCH("sub_price",Inputs!$A$2:$A$121,0)) | D41: =INDEX(Inputs!$M$2:$M$121,MATCH("sub_price",Inputs!$A$2:$A$121,0)) | E41: From Inputs, key sub_price
...

Sheet Projection
A1: Projection: 24 months, model (a) bank licence, one partner bank
A2: Pilot fee spread over the pilot months, then the larger of licence revenue and the platform floor. Costs are fixed plus embedded variable cost per MAU.
A4: Conservative
A5: Month | B5: 1 | C5: 2 | D5: 3 | E5: 4 | F5: 5 | G5: 6 | H5: 7 | I5: 8 | J5: 9 | K5: 10 | L5: 11 | M5: 12 | N5: 13 | O5: 14 | P5: 15 | Q5: 16 | R5: 17 | S5: 18 | T5: 19 | U5: 20 | V5: 21 | W5: 22 | X5: 23 | Y5: 24
A6: MAU | B6: =IF(B$5<=Model!$B$65,Model!$B$76*Model!$B$66*B$5/Model!$B$65,MIN(Model!$B$76,Model!$B$76*Model!$B$66+(Model!$B$76-Model!$B$76*Model!$B$66)*(B$5-Model!$B$65)/Model!$B$67)) | C6: =IF(C$5<=Model!$B$65,Model!$B$76*Model!$B$66*C$5/Model!$B$65,MIN(Model!$B$76,Model!$B$76*Model!$B$66+(Model!$B$76-Model!$B$76*Model!$B$66)*(C$5-Model!$B$65)/Model!$B$67)) | D6: =IF(D$5<=Model!$B$65,Model!$B$76*Model!$B$66*D$5/Model!$B$65,MIN(Model!$B$76,Model!$B$76*Model!$B$66+(Model!$B$76-Model!$B$76*Model!$B$66)*(D$5-Model!$B$65)/Model!$B$67)) | E6: =IF(E$5<=Model!$B$65,Model!$B$76*Model!$B$66*E$5/Model!$B$65,MIN(Model!$B$76,Model!$B$76*Model!$B$66+(Model!$B$76-Model!$B$76*Model!$B$66)*(E$5-Model!$B$65)/Model!$B$67)) | F6: =IF(F$5<=Model!$B$65,Model!$B$76*Model!$B$66*F$5/Model!$B$65,MIN(Model!$B$76,Model!$B$76*Model!$B$66+(Model!$B$76-Model!$B$76*Model!$B$66)*(F$5-Model!$B$65)/Model!$B$67)) | G6: =IF(G$5<=Model!$B$65,Model!$B$76*Model!$B$66*G$5/Model!$B$65,MIN(Model!$B$76,Model!$B$76*Model!$B$66+(Model!$B$76-Model!$B$76*Model!$B$66)*(G$5-Model!$B$65)/Model!$B$67)) | H6: =IF(H$5<=Model!$B$65,Model!$B$76*Model!$B$66*H$5/Model!$B$65,MIN(Model!$B$76,Model!$B$76*Model!$B$66+(Model!$B$76-Model!$B$76*Model!$B$66)*(H$5-Model!$B$65)/Model!$B$67)) | I6: =IF(I$5<=Model!$B$65,Model!$B$76*Model!$B$66*I$5/Model!$B$65,MIN(Model!$B$76,Model!$B$76*Model!$B$66+(Model!$B$76-Model!$B$76*Model!$B$66)*(I$5-Model!$B$65)/Model!$B$67)) | ... Y6: =IF(Y$5<=Model!$B$65,Model!$B$76*Model!$B$66*Y$5/Model!$B$65,MIN(Model!$B$76,Model!$B$76*Model!$B$66+(Model!$B$76-Model!$B$76*Model!$B$66)*(Y$5-Model!$B$65)/Model!$B$67))
A7: Revenue | B7: =IF(B$5<=Model!$B$65,Model!$B$38/Model!$B$65,MAX(Model!$B$37*B6,Model!$B$39/12)) | C7: =IF(C$5<=Model!$B$65,Model!$B$38/Model!$B$65,MAX(Model!$B$37*C6,Model!$B$39/12)) | D7: =IF(D$5<=Model!$B$65,Model!$B$38/Model!$B$65,MAX(Model!$B$37*D6,Model!$B$39/12)) | E7: =IF(E$5<=Model!$B$65,Model!$B$38/Model!$B$65,MAX(Model!$B$37*E6,Model!$B$39/12)) | F7: =IF(F$5<=Model!$B$65,Model!$B$38/Model!$B$65,MAX(Model!$B$37*F6,Model!$B$39/12)) | G7: =IF(G$5<=Model!$B$65,Model!$B$38/Model!$B$65,MAX(Model!$B$37*G6,Model!$B$39/12)) | H7: =IF(H$5<=Model!$B$65,Model!$B$38/Model!$B$65,MAX(Model!$B$37*H6,Model!$B$39/12)) | I7: =IF(I$5<=Model!$B$65,Model!$B$38/Model!$B$65,MAX(Model!$B$37*I6,Model!$B$39/12)) | ... Y7: =IF(Y$5<=Model!$B$65,Model!$B$38/Model!$B$65,MAX(Model!$B$37*Y6,Model!$B$39/12))
A8: Fixed cost | B8: =Model!$B$87 | C8: =Model!$B$87 | D8: =Model!$B$87 | E8: =Model!$B$87 | F8: =Model!$B$87 | G8: =Model!$B$87 | H8: =Model!$B$87 | I8: =Model!$B$87 | ... Y8: =Model!$B$87
A9: Variable cost | B9: =Model!$B$84*B6 | C9: =Model!$B$84*C6 | D9: =Model!$B$84*D6 | E9: =Model!$B$84*E6 | F9: =Model!$B$84*F6 | G9: =Model!$B$84*G6 | H9: =Model!$B$84*H6 | I9: =Model!$B$84*I6 | ... Y9: =Model!$B$84*Y6
A10: Net cash flow | B10: =B7-B8-B9 | C10: =C7-C8-C9 | D10: =D7-D8-D9 | E10: =E7-E8-E9 | F10: =F7-F8-F9 | G10: =G7-G8-G9 | H10: =H7-H8-H9 | I10: =I7-I8-I9 | ... Y10: =Y7-Y8-Y9
A11: Cumulative cash | B11: =B10+INDEX(Inputs!$L$2:$L$121,MATCH("opening_cash",Inputs!$A$2:$A$121,0)) | C11: =C10+B11 | D11: =D10+C11 | E11: =E10+D11 | F11: =F10+E11 | G11: =G10+F11 | H11: =H10+G11 | I11: =I10+H11 | J11: =J10+I11 | ... Y11: =Y10+X11
A12: Profitable month flag | B12: =IF(B10>0,1,0) | C12: =IF(C10>0,1,0) | D12: =IF(D10>0,1,0) | E12: =IF(E10>0,1,0) | F12: =IF(F10>0,1,0) | G12: =IF(G10>0,1,0) | H12: =IF(H10>0,1,0) | I12: =IF(I10>0,1,0) | ... Y12: =IF(Y10>0,1,0)
A14: First profitable month | B14: =IFERROR(MATCH(1,B12:Y12,0),"beyond 24")
A15: Peak funding need (ZAR) | B15: =MAX(0,-MIN(B11:Y11))
A16: Cumulative cash at month 24 (ZAR) | B16: =Y11
A17: Revenue in year 2 (ZAR) | B17: =SUM(N7:Y7)
A20: Base
A21: Month | B21: 1 | C21: 2 | D21: 3 | E21: 4 | F21: 5 | G21: 6 | H21: 7 | I21: 8 | J21: 9 | K21: 10 | L21: 11 | M21: 12 | N21: 13 | O21: 14 | P21: 15 | Q21: 16 | R21: 17 | S21: 18 | T21: 19 | U21: 20 | V21: 21 | W21: 22 | X21: 23 | Y21: 24
A22: MAU | B22: =IF(B$21<=Model!$C$65,Model!$C$76*Model!$C$66*B$21/Model!$C$65,MIN(Model!$C$76,Model!$C$76*Model!$C$66+(Model!$C$76-Model!$C$76*Model!$C$66)*(B$21-Model!$C$65)/Model!$C$67)) | C22: =IF(C$21<=Model!$C$65,Model!$C$76*Model!$C$66*C$21/Model!$C$65,MIN(Model!$C$76,Model!$C$76*Model!$C$66+(Model!$C$76-Model!$C$76*Model!$C$66)*(C$21-Model!$C$65)/Model!$C$67)) | D22: =IF(D$21<=Model!$C$65,Model!$C$76*Model!$C$66*D$21/Model!$C$65,MIN(Model!$C$76,Model!$C$76*Model!$C$66+(Model!$C$76-Model!$C$76*Model!$C$66)*(D$21-Model!$C$65)/Model!$C$67)) | E22: =IF(E$21<=Model!$C$65,Model!$C$76*Model!$C$66*E$21/Model!$C$65,MIN(Model!$C$76,Model!$C$76*Model!$C$66+(Model!$C$76-Model!$C$76*Model!$C$66)*(E$21-Model!$C$65)/Model!$C$67)) | F22: =IF(F$21<=Model!$C$65,Model!$C$76*Model!$C$66*F$21/Model!$C$65,MIN(Model!$C$76,Model!$C$76*Model!$C$66+(Model!$C$76-Model!$C$76*Model!$C$66)*(F$21-Model!$C$65)/Model!$C$67)) | G22: =IF(G$21<=Model!$C$65,Model!$C$76*Model!$C$66*G$21/Model!$C$65,MIN(Model!$C$76,Model!$C$76*Model!$C$66+(Model!$C$76-Model!$C$76*Model!$C$66)*(G$21-Model!$C$65)/Model!$C$67)) | H22: =IF(H$21<=Model!$C$65,Model!$C$76*Model!$C$66*H$21/Model!$C$65,MIN(Model!$C$76,Model!$C$76*Model!$C$66+(Model!$C$76-Model!$C$76*Model!$C$66)*(H$21-Model!$C$65)/Model!$C$67)) | I22: =IF(I$21<=Model!$C$65,Model!$C$76*Model!$C$66*I$21/Model!$C$65,MIN(Model!$C$76,Model!$C$76*Model!$C$66+(Model!$C$76-Model!$C$76*Model!$C$66)*(I$21-Model!$C$65)/Model!$C$67)) | ... Y22: =IF(Y$21<=Model!$C$65,Model!$C$76*Model!$C$66*Y$21/Model!$C$65,MIN(Model!$C$76,Model!$C$76*Model!$C$66+(Model!$C$76-Model!$C$76*Model!$C$66)*(Y$21-Model!$C$65)/Model!$C$67))
A23: Revenue | B23: =IF(B$21<=Model!$C$65,Model!$C$38/Model!$C$65,MAX(Model!$C$37*B22,Model!$C$39/12)) | C23: =IF(C$21<=Model!$C$65,Model!$C$38/Model!$C$65,MAX(Model!$C$37*C22,Model!$C$39/12)) | D23: =IF(D$21<=Model!$C$65,Model!$C$38/Model!$C$65,MAX(Model!$C$37*D22,Model!$C$39/12)) | E23: =IF(E$21<=Model!$C$65,Model!$C$38/Model!$C$65,MAX(Model!$C$37*E22,Model!$C$39/12)) | F23: =IF(F$21<=Model!$C$65,Model!$C$38/Model!$C$65,MAX(Model!$C$37*F22,Model!$C$39/12)) | G23: =IF(G$21<=Model!$C$65,Model!$C$38/Model!$C$65,MAX(Model!$C$37*G22,Model!$C$39/12)) | H23: =IF(H$21<=Model!$C$65,Model!$C$38/Model!$C$65,MAX(Model!$C$37*H22,Model!$C$39/12)) | I23: =IF(I$21<=Model!$C$65,Model!$C$38/Model!$C$65,MAX(Model!$C$37*I22,Model!$C$39/12)) | ... Y23: =IF(Y$21<=Model!$C$65,Model!$C$38/Model!$C$65,MAX(Model!$C$37*Y22,Model!$C$39/12))
A24: Fixed cost | B24: =Model!$C$87 | C24: =Model!$C$87 | D24: =Model!$C$87 | E24: =Model!$C$87 | F24: =Model!$C$87 | G24: =Model!$C$87 | H24: =Model!$C$87 | I24: =Model!$C$87 | ... Y24: =Model!$C$87
A25: Variable cost | B25: =Model!$C$84*B22 | C25: =Model!$C$84*C22 | D25: =Model!$C$84*D22 | E25: =Model!$C$84*E22 | F25: =Model!$C$84*F22 | G25: =Model!$C$84*G22 | H25: =Model!$C$84*H22 | I25: =Model!$C$84*I22 | ... Y25: =Model!$C$84*Y22
A26: Net cash flow | B26: =B23-B24-B25 | C26: =C23-C24-C25 | D26: =D23-D24-D25 | E26: =E23-E24-E25 | F26: =F23-F24-F25 | G26: =G23-G24-G25 | H26: =H23-H24-H25 | I26: =I23-I24-I25 | ... Y26: =Y23-Y24-Y25
A27: Cumulative cash | B27: =B26+INDEX(Inputs!$L$2:$L$121,MATCH("opening_cash",Inputs!$A$2:$A$121,0)) | C27: =C26+B27 | D27: =D26+C27 | E27: =E26+D27 | F27: =F26+E27 | G27: =G26+F27 | H27: =H26+G27 | I27: =I26+H27 | J27: =J26+I27 | ... Y27: =Y26+X27
A28: Profitable month flag | B28: =IF(B26>0,1,0) | C28: =IF(C26>0,1,0) | D28: =IF(D26>0,1,0) | E28: =IF(E26>0,1,0) | F28: =IF(F26>0,1,0) | G28: =IF(G26>0,1,0) | H28: =IF(H26>0,1,0) | I28: =IF(I26>0,1,0) | ... Y28: =IF(Y26>0,1,0)
A30: First profitable month | B30: =IFERROR(MATCH(1,B28:Y28,0),"beyond 24")
A31: Peak funding need (ZAR) | B31: =MAX(0,-MIN(B27:Y27))
A32: Cumulative cash at month 24 (ZAR) | B32: =Y27
A33: Revenue in year 2 (ZAR) | B33: =SUM(N23:Y23)
A36: Ambitious
A37: Month | B37: 1 | C37: 2 | D37: 3 | E37: 4 | F37: 5 | G37: 6 | H37: 7 | I37: 8 | J37: 9 | K37: 10 | L37: 11 | M37: 12 | N37: 13 | O37: 14 | P37: 15 | Q37: 16 | R37: 17 | S37: 18 | T37: 19 | U37: 20 | V37: 21 | W37: 22 | X37: 23 | Y37: 24
A38: MAU | B38: =IF(B$37<=Model!$D$65,Model!$D$76*Model!$D$66*B$37/Model!$D$65,MIN(Model!$D$76,Model!$D$76*Model!$D$66+(Model!$D$76-Model!$D$76*Model!$D$66)*(B$37-Model!$D$65)/Model!$D$67)) | C38: =IF(C$37<=Model!$D$65,Model!$D$76*Model!$D$66*C$37/Model!$D$65,MIN(Model!$D$76,Model!$D$76*Model!$D$66+(Model!$D$76-Model!$D$76*Model!$D$66)*(C$37-Model!$D$65)/Model!$D$67)) | D38: =IF(D$37<=Model!$D$65,Model!$D$76*Model!$D$66*D$37/Model!$D$65,MIN(Model!$D$76,Model!$D$76*Model!$D$66+(Model!$D$76-Model!$D$76*Model!$D$66)*(D$37-Model!$D$65)/Model!$D$67)) | E38: =IF(E$37<=Model!$D$65,Model!$D$76*Model!$D$66*E$37/Model!$D$65,MIN(Model!$D$76,Model!$D$76*Model!$D$66+(Model!$D$76-Model!$D$76*Model!$D$66)*(E$37-Model!$D$65)/Model!$D$67)) | F38: =IF(F$37<=Model!$D$65,Model!$D$76*Model!$D$66*F$37/Model!$D$65,MIN(Model!$D$76,Model!$D$76*Model!$D$66+(Model!$D$76-Model!$D$76*Model!$D$66)*(F$37-Model!$D$65)/Model!$D$67)) | G38: =IF(G$37<=Model!$D$65,Model!$D$76*Model!$D$66*G$37/Model!$D$65,MIN(Model!$D$76,Model!$D$76*Model!$D$66+(Model!$D$76-Model!$D$76*Model!$D$66)*(G$37-Model!$D$65)/Model!$D$67)) | H38: =IF(H$37<=Model!$D$65,Model!$D$76*Model!$D$66*H$37/Model!$D$65,MIN(Model!$D$76,Model!$D$76*Model!$D$66+(Model!$D$76-Model!$D$76*Model!$D$66)*(H$37-Model!$D$65)/Model!$D$67)) | I38: =IF(I$37<=Model!$D$65,Model!$D$76*Model!$D$66*I$37/Model!$D$65,MIN(Model!$D$76,Model!$D$76*Model!$D$66+(Model!$D$76-Model!$D$76*Model!$D$66)*(I$37-Model!$D$65)/Model!$D$67)) | ... Y38: =IF(Y$37<=Model!$D$65,Model!$D$76*Model!$D$66*Y$37/Model!$D$65,MIN(Model!$D$76,Model!$D$76*Model!$D$66+(Model!$D$76-Model!$D$76*Model!$D$66)*(Y$37-Model!$D$65)/Model!$D$67))
A39: Revenue | B39: =IF(B$37<=Model!$D$65,Model!$D$38/Model!$D$65,MAX(Model!$D$37*B38,Model!$D$39/12)) | C39: =IF(C$37<=Model!$D$65,Model!$D$38/Model!$D$65,MAX(Model!$D$37*C38,Model!$D$39/12)) | D39: =IF(D$37<=Model!$D$65,Model!$D$38/Model!$D$65,MAX(Model!$D$37*D38,Model!$D$39/12)) | E39: =IF(E$37<=Model!$D$65,Model!$D$38/Model!$D$65,MAX(Model!$D$37*E38,Model!$D$39/12)) | F39: =IF(F$37<=Model!$D$65,Model!$D$38/Model!$D$65,MAX(Model!$D$37*F38,Model!$D$39/12)) | G39: =IF(G$37<=Model!$D$65,Model!$D$38/Model!$D$65,MAX(Model!$D$37*G38,Model!$D$39/12)) | H39: =IF(H$37<=Model!$D$65,Model!$D$38/Model!$D$65,MAX(Model!$D$37*H38,Model!$D$39/12)) | I39: =IF(I$37<=Model!$D$65,Model!$D$38/Model!$D$65,MAX(Model!$D$37*I38,Model!$D$39/12)) | ... Y39: =IF(Y$37<=Model!$D$65,Model!$D$38/Model!$D$65,MAX(Model!$D$37*Y38,Model!$D$39/12))
A40: Fixed cost | B40: =Model!$D$87 | C40: =Model!$D$87 | D40: =Model!$D$87 | E40: =Model!$D$87 | F40: =Model!$D$87 | G40: =Model!$D$87 | H40: =Model!$D$87 | I40: =Model!$D$87 | ... Y40: =Model!$D$87
A41: Variable cost | B41: =Model!$D$84*B38 | C41: =Model!$D$84*C38 | D41: =Model!$D$84*D38 | E41: =Model!$D$84*E38 | F41: =Model!$D$84*F38 | G41: =Model!$D$84*G38 | H41: =Model!$D$84*H38 | I41: =Model!$D$84*I38 | ... Y41: =Model!$D$84*Y38
A42: Net cash flow | B42: =B39-B40-B41 | C42: =C39-C40-C41 | D42: =D39-D40-D41 | E42: =E39-E40-E41 | F42: =F39-F40-F41 | G42: =G39-G40-G41 | H42: =H39-H40-H41 | I42: =I39-I40-I41 | ... Y42: =Y39-Y40-Y41
A43: Cumulative cash | B43: =B42+INDEX(Inputs!$L$2:$L$121,MATCH("opening_cash",Inputs!$A$2:$A$121,0)) | C43: =C42+B43 | D43: =D42+C43 | E43: =E42+D43 | F43: =F42+E43 | G43: =G42+F43 | H43: =H42+G43 | I43: =I42+H43 | J43: =J42+I43 | ... Y43: =Y42+X43
A44: Profitable month flag | B44: =IF(B42>0,1,0) | C44: =IF(C42>0,1,0) | D44: =IF(D42>0,1,0) | E44: =IF(E42>0,1,0) | F44: =IF(F42>0,1,0) | G44: =IF(G42>0,1,0) | H44: =IF(H42>0,1,0) | I44: =IF(I42>0,1,0) | ... Y44: =IF(Y42>0,1,0)
A46: First profitable month | B46: =IFERROR(MATCH(1,B44:Y44,0),"beyond 24")
A47: Peak funding need (ZAR) | B47: =MAX(0,-MIN(B43:Y43))
A48: Cumulative cash at month 24 (ZAR) | B48: =Y43
...

Sheet Sensitivity
A1: Sensitivity (Base scenario, one input at a time)
A3: Break-even MAU for model (a) | B3: Input at low | C3: Input at high | D3: MAU at low | E3: MAU at high | F3: Swing | G3: Base MAU
A4: Base case | G4: =IFERROR(IF(INDEX(Inputs!$E$2:$E$121,MATCH("lic_fee_per_mau",Inputs!$A$2:$A$121,0))-(INDEX(Inputs!$E$2:$E$121,MATCH("hosting_per_mau",Inputs!$A$2:$A$121,0))+INDEX(Inputs!$E$2:$E$121,MATCH("forecast_compute",Inputs!$A$2:$A$121,0))+(INDEX(Inputs!$E$2:$E$121,MATCH("tokens_in_msg",Inputs!$A$2:$A$121,0))*INDEX(Inputs!$E$2:$E$121,MATCH("llm_in_price",Inputs!$A$2:$A$121,0))+INDEX(Inputs!$E$2:$E$121,MATCH("tokens_out_msg",Inputs!$A$2:$A$121,0))*INDEX(Inputs!$E$2:$E$121,MATCH("llm_out_price",Inputs!$A$2:$A$121,0)))/1000000*INDEX(Inputs!$E$2:$E$121,MATCH("usd_zar",Inputs!$A$2:$A$121,0))*INDEX(Inputs!$E$2:$E$121,MATCH("msgs_per_month",Inputs!$A$2:$A$121,0))+INDEX(Inputs!$E$2:$E$121,MATCH("push_cost",Inputs!$A$2:$A$121,0))*INDEX(Inputs!$E$2:$E$121,MATCH("msgs_per_month",Inputs!$A$2:$A$121,0))+INDEX(Inputs!$E$2:$E$121,MATCH("support_per_mau",Inputs!$A$2:$A$121,0)))>0,(INDEX(Inputs!$E$2:$E$121,MATCH("team_fixed",Inputs!$A$2:$A$121,0))+INDEX(Inputs!$E$2:$E$121,MATCH("compliance_fixed",Inputs!$A$2:$A$121,0))+INDEX(Inputs!$E$2:$E$121,MATCH("db_base",Inputs!$A$2:$A$121,0))*INDEX(Inputs!$E$2:$E$121,MATCH("usd_zar",Inputs!$A$2:$A$121,0)))/(INDEX(Inputs!$E$2:$E$121,MATCH("lic_fee_per_mau",Inputs!$A$2:$A$121,0))-(INDEX(Inputs!$E$2:$E$121,MATCH("hosting_per_mau",Inputs!$A$2:$A$121,0))+INDEX(Inputs!$E$2:$E$121,MATCH("forecast_compute",Inputs!$A$2:$A$121,0))+(INDEX(Inputs!$E$2:$E$121,MATCH("tokens_in_msg",Inputs!$A$2:$A$121,0))*INDEX(Inputs!$E$2:$E$121,MATCH("llm_in_price",Inputs!$A$2:$A$121,0))+INDEX(Inputs!$E$2:$E$121,MATCH("tokens_out_msg",Inputs!$A$2:$A$121,0))*INDEX(Inputs!$E$2:$E$121,MATCH("llm_out_price",Inputs!$A$2:$A$121,0)))/1000000*INDEX(Inputs!$E$2:$E$121,MATCH("usd_zar",Inputs!$A$2:$A$121,0))*INDEX(Inputs!$E$2:$E$121,MATCH("msgs_per_month",Inputs!$A$2:$A$121,0))+INDEX(Inputs!$E$2:$E$121,MATCH("push_cost",Inputs!$A$2:$A$121,0))*INDEX(Inputs!$E$2:$E$121,MATCH("msgs_per_month",Inputs!$A$2:$A$121,0))+INDEX(Inputs!$E$2:$E$121,MATCH("support_per_mau",Inputs!$A$2:$A$121,0)))),""),"")
A5: lic_fee_per_mau | B5: =INDEX(Inputs!$D$2:$D$121,MATCH("lic_fee_per_mau",Inputs!$A$2:$A$121,0)) | C5: =INDEX(Inputs!$F$2:$F$121,MATCH("lic_fee_per_mau",Inputs!$A$2:$A$121,0)) | D5: =IFERROR(IF(INDEX(Inputs!$D$2:$D$121,MATCH("lic_fee_per_mau",Inputs!$A$2:$A$121,0))-(INDEX(Inputs!$E$2:$E$121,MATCH("hosting_per_mau",Inputs!$A$2:$A$121,0))+INDEX(Inputs!$E$2:$E$121,MATCH("forecast_compute",Inputs!$A$2:$A$121,0))+(INDEX(Inputs!$E$2:$E$121,MATCH("tokens_in_msg",Inputs!$A$2:$A$121,0))*INDEX(Inputs!$E$2:$E$121,MATCH("llm_in_price",Inputs!$A$2:$A$121,0))+INDEX(Inputs!$E$2:$E$121,MATCH("tokens_out_msg",Inputs!$A$2:$A$121,0))*INDEX(Inputs!$E$2:$E$121,MATCH("llm_out_price",Inputs!$A$2:$A$121,0)))/1000000*INDEX(Inputs!$E$2:$E$121,MATCH("usd_zar",Inputs!$A$2:$A$121,0))*INDEX(Inputs!$E$2:$E$121,MATCH("msgs_per_month",Inputs!$A$2:$A$121,0))+INDEX(Inputs!$E$2:$E$121,MATCH("push_cost",Inputs!$A$2:$A$121,0))*INDEX(Inputs!$E$2:$E$121,MATCH("msgs_per_month",Inputs!$A$2:$A$121,0))+INDEX(Inputs!$E$2:$E$121,MATCH("support_per_mau",Inputs!$A$2:$A$121,0)))>0,(INDEX(Inputs!$E$2:$E$121,MATCH("team_fixed",Inputs!$A$2:$A$121,0))+INDEX(Inputs!$E$2:$E$121,MATCH("compliance_fixed",Inputs!$A$2:$A$121,0))+INDEX(Inputs!$E$2:$E$121,MATCH("db_base",Inputs!$A$2:$A$121,0))*INDEX(Inputs!$E$2:$E$121,MATCH("usd_zar",Inputs!$A$2:$A$121,0)))/(INDEX(Inputs!$D$2:$D$121,MATCH("lic_fee_per_mau",Inputs!$A$2:$A$121,0))-(INDEX(Inputs!$E$2:$E$121,MATCH("hosting_per_mau",Inputs!$A$2:$A$121,0))+INDEX(Inputs!$E$2:$E$121,MATCH("forecast_compute",Inputs!$A$2:$A$121,0))+(INDEX(Inputs!$E$2:$E$121,MATCH("tokens_in_msg",Inputs!$A$2:$A$121,0))*INDEX(Inputs!$E$2:$E$121,MATCH("llm_in_price",Inputs!$A$2:$A$121,0))+INDEX(Inputs!$E$2:$E$121,MATCH("tokens_out_msg",Inputs!$A$2:$A$121,0))*INDEX(Inputs!$E$2:$E$121,MATCH("llm_out_price",Inputs!$A$2:$A$121,0)))/1000000*INDEX(Inputs!$E$2:$E$121,MATCH("usd_zar",Inputs!$A$2:$A$121,0))*INDEX(Inputs!$E$2:$E$121,MATCH("msgs_per_month",Inputs!$A$2:$A$121,0))+INDEX(Inputs!$E$2:$E$121,MATCH("push_cost",Inputs!$A$2:$A$121,0))*INDEX(Inputs!$E$2:$E$121,MATCH("msgs_per_month",Inputs!$A$2:$A$121,0))+INDEX(Inputs!$E$2:$E$121,MATCH("support_per_mau",Inputs!$A$2:$A$121,0)))),""),"") | E5: =IFERROR(IF(INDEX(Inputs!$F$2:$F$121,MATCH("lic_fee_per_mau",Inputs!$A$2:$A$121,0))-(INDEX(Inputs!$E$2:$E$121,MATCH("hosting_per_mau",Inputs!$A$2:$A$121,0))+INDEX(Inputs!$E$2:$E$121,MATCH("forecast_compute",Inputs!$A$2:$A$121,0))+(INDEX(Inputs!$E$2:$E$121,MATCH("tokens_in_msg",Inputs!$A$2:$A$121,0))*INDEX(Inputs!$E$2:$E$121,MATCH("llm_in_price",Inputs!$A$2:$A$121,0))+INDEX(Inputs!$E$2:$E$121,MATCH("tokens_out_msg",Inputs!$A$2:$A$121,0))*INDEX(Inputs!$E$2:$E$121,MATCH("llm_out_price",Inputs!$A$2:$A$121,0)))/1000000*INDEX(Inputs!$E$2:$E$121,MATCH("usd_zar",Inputs!$A$2:$A$121,0))*INDEX(Inputs!$E$2:$E$121,MATCH("msgs_per_month",Inputs!$A$2:$A$121,0))+INDEX(Inputs!$E$2:$E$121,MATCH("push_cost",Inputs!$A$2:$A$121,0))*INDEX(Inputs!$E$2:$E$121,MATCH("msgs_per_month",Inputs!$A$2:$A$121,0))+INDEX(Inputs!$E$2:$E$121,MATCH("support_per_mau",Inputs!$A$2:$A$121,0)))>0,(INDEX(Inputs!$E$2:$E$121,MATCH("team_fixed",Inputs!$A$2:$A$121,0))+INDEX(Inputs!$E$2:$E$121,MATCH("compliance_fixed",Inputs!$A$2:$A$121,0))+INDEX(Inputs!$E$2:$E$121,MATCH("db_base",Inputs!$A$2:$A$121,0))*INDEX(Inputs!$E$2:$E$121,MATCH("usd_zar",Inputs!$A$2:$A$121,0)))/(INDEX(Inputs!$F$2:$F$121,MATCH("lic_fee_per_mau",Inputs!$A$2:$A$121,0))-(INDEX(Inputs!$E$2:$E$121,MATCH("hosting_per_mau",Inputs!$A$2:$A$121,0))+INDEX(Inputs!$E$2:$E$121,MATCH("forecast_compute",Inputs!$A$2:$A$121,0))+(INDEX(Inputs!$E$2:$E$121,MATCH("tokens_in_msg",Inputs!$A$2:$A$121,0))*INDEX(Inputs!$E$2:$E$121,MATCH("llm_in_price",Inputs!$A$2:$A$121,0))+INDEX(Inputs!$E$2:$E$121,MATCH("tokens_out_msg",Inputs!$A$2:$A$121,0))*INDEX(Inputs!$E$2:$E$121,MATCH("llm_out_price",Inputs!$A$2:$A$121,0)))/1000000*INDEX(Inputs!$E$2:$E$121,MATCH("usd_zar",Inputs!$A$2:$A$121,0))*INDEX(Inputs!$E$2:$E$121,MATCH("msgs_per_month",Inputs!$A$2:$A$121,0))+INDEX(Inputs!$E$2:$E$121,MATCH("push_cost",Inputs!$A$2:$A$121,0))*INDEX(Inputs!$E$2:$E$121,MATCH("msgs_per_month",Inputs!$A$2:$A$121,0))+INDEX(Inputs!$E$2:$E$121,MATCH("support_per_mau",Inputs!$A$2:$A$121,0)))),""),"") | F5: =IFERROR(ABS(E5-D5),"") | G5: =$G$4
A6: team_fixed | B6: =INDEX(Inputs!$D$2:$D$121,MATCH("team_fixed",Inputs!$A$2:$A$121,0)) | C6: =INDEX(Inputs!$F$2:$F$121,MATCH("team_fixed",Inputs!$A$2:$A$121,0)) | D6: =IFERROR(IF(INDEX(Inputs!$E$2:$E$121,MATCH("lic_fee_per_mau",Inputs!$A$2:$A$121,0))-(INDEX(Inputs!$E$2:$E$121,MATCH("hosting_per_mau",Inputs!$A$2:$A$121,0))+INDEX(Inputs!$E$2:$E$121,MATCH("forecast_compute",Inputs!$A$2:$A$121,0))+(INDEX(Inputs!$E$2:$E$121,MATCH("tokens_in_msg",Inputs!$A$2:$A$121,0))*INDEX(Inputs!$E$2:$E$121,MATCH("llm_in_price",Inputs!$A$2:$A$121,0))+INDEX(Inputs!$E$2:$E$121,MATCH("tokens_out_msg",Inputs!$A$2:$A$121,0))*INDEX(Inputs!$E$2:$E$121,MATCH("llm_out_price",Inputs!$A$2:$A$121,0)))/1000000*INDEX(Inputs!$E$2:$E$121,MATCH("usd_zar",Inputs!$A$2:$A$121,0))*INDEX(Inputs!$E$2:$E$121,MATCH("msgs_per_month",Inputs!$A$2:$A$121,0))+INDEX(Inputs!$E$2:$E$121,MATCH("push_cost",Inputs!$A$2:$A$121,0))*INDEX(Inputs!$E$2:$E$121,MATCH("msgs_per_month",Inputs!$A$2:$A$121,0))+INDEX(Inputs!$E$2:$E$121,MATCH("support_per_mau",Inputs!$A$2:$A$121,0)))>0,(INDEX(Inputs!$D$2:$D$121,MATCH("team_fixed",Inputs!$A$2:$A$121,0))+INDEX(Inputs!$E$2:$E$121,MATCH("compliance_fixed",Inputs!$A$2:$A$121,0))+INDEX(Inputs!$E$2:$E$121,MATCH("db_base",Inputs!$A$2:$A$121,0))*INDEX(Inputs!$E$2:$E$121,MATCH("usd_zar",Inputs!$A$2:$A$121,0)))/(INDEX(Inputs!$E$2:$E$121,MATCH("lic_fee_per_mau",Inputs!$A$2:$A$121,0))-(INDEX(Inputs!$E$2:$E$121,MATCH("hosting_per_mau",Inputs!$A$2:$A$121,0))+INDEX(Inputs!$E$2:$E$121,MATCH("forecast_compute",Inputs!$A$2:$A$121,0))+(INDEX(Inputs!$E$2:$E$121,MATCH("tokens_in_msg",Inputs!$A$2:$A$121,0))*INDEX(Inputs!$E$2:$E$121,MATCH("llm_in_price",Inputs!$A$2:$A$121,0))+INDEX(Inputs!$E$2:$E$121,MATCH("tokens_out_msg",Inputs!$A$2:$A$121,0))*INDEX(Inputs!$E$2:$E$121,MATCH("llm_out_price",Inputs!$A$2:$A$121,0)))/1000000*INDEX(Inputs!$E$2:$E$121,MATCH("usd_zar",Inputs!$A$2:$A$121,0))*INDEX(Inputs!$E$2:$E$121,MATCH("msgs_per_month",Inputs!$A$2:$A$121,0))+INDEX(Inputs!$E$2:$E$121,MATCH("push_cost",Inputs!$A$2:$A$121,0))*INDEX(Inputs!$E$2:$E$121,MATCH("msgs_per_month",Inputs!$A$2:$A$121,0))+INDEX(Inputs!$E$2:$E$121,MATCH("support_per_mau",Inputs!$A$2:$A$121,0)))),""),"") | E6: =IFERROR(IF(INDEX(Inputs!$E$2:$E$121,MATCH("lic_fee_per_mau",Inputs!$A$2:$A$121,0))-(INDEX(Inputs!$E$2:$E$121,MATCH("hosting_per_mau",Inputs!$A$2:$A$121,0))+INDEX(Inputs!$E$2:$E$121,MATCH("forecast_compute",Inputs!$A$2:$A$121,0))+(INDEX(Inputs!$E$2:$E$121,MATCH("tokens_in_msg",Inputs!$A$2:$A$121,0))*INDEX(Inputs!$E$2:$E$121,MATCH("llm_in_price",Inputs!$A$2:$A$121,0))+INDEX(Inputs!$E$2:$E$121,MATCH("tokens_out_msg",Inputs!$A$2:$A$121,0))*INDEX(Inputs!$E$2:$E$121,MATCH("llm_out_price",Inputs!$A$2:$A$121,0)))/1000000*INDEX(Inputs!$E$2:$E$121,MATCH("usd_zar",Inputs!$A$2:$A$121,0))*INDEX(Inputs!$E$2:$E$121,MATCH("msgs_per_month",Inputs!$A$2:$A$121,0))+INDEX(Inputs!$E$2:$E$121,MATCH("push_cost",Inputs!$A$2:$A$121,0))*INDEX(Inputs!$E$2:$E$121,MATCH("msgs_per_month",Inputs!$A$2:$A$121,0))+INDEX(Inputs!$E$2:$E$121,MATCH("support_per_mau",Inputs!$A$2:$A$121,0)))>0,(INDEX(Inputs!$F$2:$F$121,MATCH("team_fixed",Inputs!$A$2:$A$121,0))+INDEX(Inputs!$E$2:$E$121,MATCH("compliance_fixed",Inputs!$A$2:$A$121,0))+INDEX(Inputs!$E$2:$E$121,MATCH("db_base",Inputs!$A$2:$A$121,0))*INDEX(Inputs!$E$2:$E$121,MATCH("usd_zar",Inputs!$A$2:$A$121,0)))/(INDEX(Inputs!$E$2:$E$121,MATCH("lic_fee_per_mau",Inputs!$A$2:$A$121,0))-(INDEX(Inputs!$E$2:$E$121,MATCH("hosting_per_mau",Inputs!$A$2:$A$121,0))+INDEX(Inputs!$E$2:$E$121,MATCH("forecast_compute",Inputs!$A$2:$A$121,0))+(INDEX(Inputs!$E$2:$E$121,MATCH("tokens_in_msg",Inputs!$A$2:$A$121,0))*INDEX(Inputs!$E$2:$E$121,MATCH("llm_in_price",Inputs!$A$2:$A$121,0))+INDEX(Inputs!$E$2:$E$121,MATCH("tokens_out_msg",Inputs!$A$2:$A$121,0))*INDEX(Inputs!$E$2:$E$121,MATCH("llm_out_price",Inputs!$A$2:$A$121,0)))/1000000*INDEX(Inputs!$E$2:$E$121,MATCH("usd_zar",Inputs!$A$2:$A$121,0))*INDEX(Inputs!$E$2:$E$121,MATCH("msgs_per_month",Inputs!$A$2:$A$121,0))+INDEX(Inputs!$E$2:$E$121,MATCH("push_cost",Inputs!$A$2:$A$121,0))*INDEX(Inputs!$E$2:$E$121,MATCH("msgs_per_month",Inputs!$A$2:$A$121,0))+INDEX(Inputs!$E$2:$E$121,MATCH("support_per_mau",Inputs!$A$2:$A$121,0)))),""),"") | F6: =IFERROR(ABS(E6-D6),"") | G6: =$G$4
A7: compliance_fixed | B7: =INDEX(Inputs!$D$2:$D$121,MATCH("compliance_fixed",Inputs!$A$2:$A$121,0)) | C7: =INDEX(Inputs!$F$2:$F$121,MATCH("compliance_fixed",Inputs!$A$2:$A$121,0)) | D7: =IFERROR(IF(INDEX(Inputs!$E$2:$E$121,MATCH("lic_fee_per_mau",Inputs!$A$2:$A$121,0))-(INDEX(Inputs!$E$2:$E$121,MATCH("hosting_per_mau",Inputs!$A$2:$A$121,0))+INDEX(Inputs!$E$2:$E$121,MATCH("forecast_compute",Inputs!$A$2:$A$121,0))+(INDEX(Inputs!$E$2:$E$121,MATCH("tokens_in_msg",Inputs!$A$2:$A$121,0))*INDEX(Inputs!$E$2:$E$121,MATCH("llm_in_price",Inputs!$A$2:$A$121,0))+INDEX(Inputs!$E$2:$E$121,MATCH("tokens_out_msg",Inputs!$A$2:$A$121,0))*INDEX(Inputs!$E$2:$E$121,MATCH("llm_out_price",Inputs!$A$2:$A$121,0)))/1000000*INDEX(Inputs!$E$2:$E$121,MATCH("usd_zar",Inputs!$A$2:$A$121,0))*INDEX(Inputs!$E$2:$E$121,MATCH("msgs_per_month",Inputs!$A$2:$A$121,0))+INDEX(Inputs!$E$2:$E$121,MATCH("push_cost",Inputs!$A$2:$A$121,0))*INDEX(Inputs!$E$2:$E$121,MATCH("msgs_per_month",Inputs!$A$2:$A$121,0))+INDEX(Inputs!$E$2:$E$121,MATCH("support_per_mau",Inputs!$A$2:$A$121,0)))>0,(INDEX(Inputs!$E$2:$E$121,MATCH("team_fixed",Inputs!$A$2:$A$121,0))+INDEX(Inputs!$D$2:$D$121,MATCH("compliance_fixed",Inputs!$A$2:$A$121,0))+INDEX(Inputs!$E$2:$E$121,MATCH("db_base",Inputs!$A$2:$A$121,0))*INDEX(Inputs!$E$2:$E$121,MATCH("usd_zar",Inputs!$A$2:$A$121,0)))/(INDEX(Inputs!$E$2:$E$121,MATCH("lic_fee_per_mau",Inputs!$A$2:$A$121,0))-(INDEX(Inputs!$E$2:$E$121,MATCH("hosting_per_mau",Inputs!$A$2:$A$121,0))+INDEX(Inputs!$E$2:$E$121,MATCH("forecast_compute",Inputs!$A$2:$A$121,0))+(INDEX(Inputs!$E$2:$E$121,MATCH("tokens_in_msg",Inputs!$A$2:$A$121,0))*INDEX(Inputs!$E$2:$E$121,MATCH("llm_in_price",Inputs!$A$2:$A$121,0))+INDEX(Inputs!$E$2:$E$121,MATCH("tokens_out_msg",Inputs!$A$2:$A$121,0))*INDEX(Inputs!$E$2:$E$121,MATCH("llm_out_price",Inputs!$A$2:$A$121,0)))/1000000*INDEX(Inputs!$E$2:$E$121,MATCH("usd_zar",Inputs!$A$2:$A$121,0))*INDEX(Inputs!$E$2:$E$121,MATCH("msgs_per_month",Inputs!$A$2:$A$121,0))+INDEX(Inputs!$E$2:$E$121,MATCH("push_cost",Inputs!$A$2:$A$121,0))*INDEX(Inputs!$E$2:$E$121,MATCH("msgs_per_month",Inputs!$A$2:$A$121,0))+INDEX(Inputs!$E$2:$E$121,MATCH("support_per_mau",Inputs!$A$2:$A$121,0)))),""),"") | E7: =IFERROR(IF(INDEX(Inputs!$E$2:$E$121,MATCH("lic_fee_per_mau",Inputs!$A$2:$A$121,0))-(INDEX(Inputs!$E$2:$E$121,MATCH("hosting_per_mau",Inputs!$A$2:$A$121,0))+INDEX(Inputs!$E$2:$E$121,MATCH("forecast_compute",Inputs!$A$2:$A$121,0))+(INDEX(Inputs!$E$2:$E$121,MATCH("tokens_in_msg",Inputs!$A$2:$A$121,0))*INDEX(Inputs!$E$2:$E$121,MATCH("llm_in_price",Inputs!$A$2:$A$121,0))+INDEX(Inputs!$E$2:$E$121,MATCH("tokens_out_msg",Inputs!$A$2:$A$121,0))*INDEX(Inputs!$E$2:$E$121,MATCH("llm_out_price",Inputs!$A$2:$A$121,0)))/1000000*INDEX(Inputs!$E$2:$E$121,MATCH("usd_zar",Inputs!$A$2:$A$121,0))*INDEX(Inputs!$E$2:$E$121,MATCH("msgs_per_month",Inputs!$A$2:$A$121,0))+INDEX(Inputs!$E$2:$E$121,MATCH("push_cost",Inputs!$A$2:$A$121,0))*INDEX(Inputs!$E$2:$E$121,MATCH("msgs_per_month",Inputs!$A$2:$A$121,0))+INDEX(Inputs!$E$2:$E$121,MATCH("support_per_mau",Inputs!$A$2:$A$121,0)))>0,(INDEX(Inputs!$E$2:$E$121,MATCH("team_fixed",Inputs!$A$2:$A$121,0))+INDEX(Inputs!$F$2:$F$121,MATCH("compliance_fixed",Inputs!$A$2:$A$121,0))+INDEX(Inputs!$E$2:$E$121,MATCH("db_base",Inputs!$A$2:$A$121,0))*INDEX(Inputs!$E$2:$E$121,MATCH("usd_zar",Inputs!$A$2:$A$121,0)))/(INDEX(Inputs!$E$2:$E$121,MATCH("lic_fee_per_mau",Inputs!$A$2:$A$121,0))-(INDEX(Inputs!$E$2:$E$121,MATCH("hosting_per_mau",Inputs!$A$2:$A$121,0))+INDEX(Inputs!$E$2:$E$121,MATCH("forecast_compute",Inputs!$A$2:$A$121,0))+(INDEX(Inputs!$E$2:$E$121,MATCH("tokens_in_msg",Inputs!$A$2:$A$121,0))*INDEX(Inputs!$E$2:$E$121,MATCH("llm_in_price",Inputs!$A$2:$A$121,0))+INDEX(Inputs!$E$2:$E$121,MATCH("tokens_out_msg",Inputs!$A$2:$A$121,0))*INDEX(Inputs!$E$2:$E$121,MATCH("llm_out_price",Inputs!$A$2:$A$121,0)))/1000000*INDEX(Inputs!$E$2:$E$121,MATCH("usd_zar",Inputs!$A$2:$A$121,0))*INDEX(Inputs!$E$2:$E$121,MATCH("msgs_per_month",Inputs!$A$2:$A$121,0))+INDEX(Inputs!$E$2:$E$121,MATCH("push_cost",Inputs!$A$2:$A$121,0))*INDEX(Inputs!$E$2:$E$121,MATCH("msgs_per_month",Inputs!$A$2:$A$121,0))+INDEX(Inputs!$E$2:$E$121,MATCH("support_per_mau",Inputs!$A$2:$A$121,0)))),""),"") | F7: =IFERROR(ABS(E7-D7),"") | G7: =$G$4
